Workbook
Name _: Sign!$B$6
Name M.Yusof: Sign!$B$5
Name Meikel_Sanjaya: Sign!$B$4
Name Mohd_Sufi: Sign!$B$2
Name Name: Sign!$A$2:$A$6
Name Nil: Sign!$B$6
Name Ronal_Gultom: Sign!$B$3
Name SPT: Sign!$E$2

Sheet Sign
A1: Name | B1: Signature
A2: Mohd_Sufi | D2: SPT
A3: Ronal_Gultom
A4: Meikel_Sanjaya
A5: M.Yusof
A6: NIL

Sheet 01
A5: Operation Month | D5: February | E5: 2026
A6: Operation Date | D6: =DATE(E5,MONTH(D5&1),1) -> 46054
A8: I. Production
A9: Sect. | C9: Description | F9: Capacity | G9: Shift II (7:00 - 15:00) | I9: Storage | J9: Shift III (15:00 - 23:00) | L9: Storage | M9: Shift I (23:00 - 7:00) | O9: Storage | P9: To Day | Q9: MTD | R9: D. Time
F10: MT/Day | G10: Product | H10: D.Time | I10: 122T... | J10: Product | K10: D.Time | L10: 122T... | M10: Product | N10: D.Time | O10: 122T... | R10: Hours
A11: 101 | C11: Feed Stream (C16-18 Raw Ester) | F11: 60 | P11: =G11+J11+M11 -> 0 | Q11: =P11 -> 0 | R11: =H11+K11+N11 -> 0
C12: Oleic Intermediate Stream | F12: 30 | P12: =G12+J12+M12 -> 0 | Q12: =P12 -> 0 | R12: =H12+K12+N12 -> 0
C13: Heavy Phase Fraction | F13: 30 | P13: =G13+J13+M13 -> 0 | Q13: =P13 -> 0 | R13: =H13+K13+N13 -> 0
A14: 102 | C14: Feed Stream (Hydrogenated C16-18) | F14: 40 | P14: =G14+J14+M14 -> 0 | Q14: =P14 -> 0 | R14: =H14+K14+N14 -> 0
C15: Feed Stream (Hydrogenated Process Stock) | F15: 40 | P15: =G15+J15+M15 -> 0 | Q15: =P15 -> 0 | R15: =H15+K15+N15 -> 0
C16: Light Volatile Fraction | F16: =F14*(2/100) -> 0.8 | P16: =G16+J16+M16 -> 0 | Q16: =P16 -> 0 | R16: =H16+K16+N16 -> 0
C17: Side Cut Fraction A | F17: =F14*12/100 -> 4.8 | P17: =G17+J17+M17 -> 0 | Q17: =P17 -> 0 | R17: =H17+K17+N17 -> 0
C18: Side Cut Fraction B | F18: - | P18: =G18+J18+M18 -> 0 | Q18: =P18 -> 0 | R18: =H18+K18+N18 -> 0
C19: Side Cut Fraction C | F19: - | P19: =G19+J19+M19 -> 0 | Q19: =P19 -> 0 | R19: =H19+K19+N19 -> 0
C20: Heavy Bottom Fraction | F20: - | P20: =G20+J20+M20 -> 0 | Q20: =P20 -> 0 | R20: =H20+K20+N20 -> 0
C21: Organic Residue Stream | F21: =F14*(0.5/100) -> 0.2 | P21: =G21+J21+M21 -> 0 | Q21: =P21 -> 0 | R21: =H21+K21+N21 -> 0
A22: 102+ | C22: Feed Stream (C8-10 Process Input)) | F22: 24 | G22: 8.819 | I22: T24 | J22: 8.822 | L22: T24 | M22: 8.812 | O22: T24 | P22: =G22+J22+M22 -> 26.453 | Q22: =P22 -> 26.453 | R22: =H22+K22+N22 -> 0
C23: Hydrogenated Product Stream | F23: 24 | G23: 8.742 | I23: T112 | J23: 8.929 | L23: T112 | M23: 8.268 | O23: T112 | P23: =G23+J23+M23 -> 25.939 | Q23: =P23 -> 25.939 | R23: =H23+K23+N23 -> 0
A24: 103+ | C24: Light Hydrocarbon Fraction | F24: 24 | G24: 8.596 | I24: T112 | J24: 8.79 | L24: T112 | M24: 8.84 | O24: T112 | P24: =G24+J24+M24 -> 26.226 | Q24: =P24 -> 26.226 | R24: =H24+K24+N24 -> 0
C25: Light End (C6) | F25: - | G25: 0.1544 | I25: T117 | J25: 0.1545 | L25: T117 | M25: 0.153 | O25: T117 | P25: =G25+J25+M25 -> 0.4619 | Q25: =P25 -> 0.4619 | R25: =H25+K25+N25 -> 0
C26: Distillation Side Cut A | F26: - | G26: 8.172 | I26: T115 | J26: 8.356 | L26: T115 | M26: 8.35 | O26: T115 | P26: =G26+J26+M26 -> 24.878 | Q26: =P26 -> 24.878 | R26: =H26+K26+N26 -> 0
C27: Distillation Side Cut B | F27: - | G27: 0 | I27: colom | J27: 0 | L27: colom | M27: 0 | O27: colom | P27: =G27+J27+M27 -> 0 | Q27: =P27 -> 0 | R27: =H27+K27+N27 -> 0
C28: Heavy Residual Stream | F28: - | G28: 0.2802 | I28: T119 | J28: 0.2988 | L28: T119 | M28: 0.304 | O28: T119 | P28: =G28+J28+M28 -> 0.883 | Q28: =P28 -> 0.883 | R28: =H28+K28+N28 -> 0
A29: 104 | C29: Feed Primary Stream (C8-10) | M29: 12.462 | O29: T120 | P29: =G29+J29+M29 -> 12.462 | Q29: =P29 -> 12.462 | R29: =H29+K29+N29 -> 0
C30: Feed Secondary Stream (Oleic Intermediate) | P30: =G30+J30+M30 -> 0 | Q30: =P30 -> 0 | R30: =H30+K30+N30 -> 0
C31: Feed Stream Auxiliary (Glycerol Phase) | M31: 2.467 | O31: T124 | P31: =G31+J31+M31 -> 2.467 | Q31: =P31 -> 2.467 | R31: =H31+K31+N31 -> 0
C32: Product Stream A (Medium Chain Ester) | G32: 10.04 | I32: T129 | L32: T129 | O32: T129 | P32: =G32+J32+M32 -> 10.04 | Q32: =P32 -> 10.04 | R32: =H32+K32+N32 -> 0
C33: Product Stream B (Distilled Chemical Output) | P33: =G33+J33+M33 -> 0 | Q33: =P33 -> 0 | R33: =H33+K33+N33 -> 0

Sheet 02
A5: Operation Month | D5: ='01'!D5 -> February | E5: ='01'!E5 -> 2026
A6: Operation Date | D6: ='01'!D6+1 -> 46055
A8: I. Production
A9: Sect. | C9: Description | F9: Capacity | G9: Shift II (7:00 - 15:00) | I9: Storage | J9: Shift III (15:00 - 23:00) | L9: Storage | M9: Shift I (23:00 - 7:00) | O9: Storage | P9: To Day | Q9: MTD | R9: D. Time
F10: MT/Day | G10: Product | H10: D.Time | I10: 122T... | J10: Product | K10: D.Time | L10: 122T... | M10: Product | N10: D.Time | O10: 122T... | R10: Hours
A11: 101 | C11: Feed Stream (C16-18 Raw Ester) | F11: 60 | P11: =G11+J11+M11 -> 0 | Q11: ='01'!Q11+P11 -> 0 | R11: =H11+K11+N11 -> 0
C12: Oleic Intermediate Stream | F12: 30 | P12: =G12+J12+M12 -> 0 | Q12: ='01'!Q12+P12 -> 0 | R12: =H12+K12+N12 -> 0
C13: Heavy Phase Fraction | F13: 30 | P13: =G13+J13+M13 -> 0 | Q13: ='01'!Q13+P13 -> 0 | R13: =H13+K13+N13 -> 0
A14: 102 | C14: Feed Stream (Hydrogenated C16-18) | F14: 40 | G14: 6.51 | I14: T96 | J14: 15.932 | L14: T96 | M14: 15.268 | O14: T96 | P14: =G14+J14+M14 -> 37.71 | Q14: ='01'!Q14+P14 -> 37.71 | R14: =H14+K14+N14 -> 0
C15: Feed Stream (Hydrogenated Process Stock) | F15: 40 | P15: =G15+J15+M15 -> 0 | Q15: ='01'!Q15+P15 -> 0 | R15: =H15+K15+N15 -> 0
C16: Light Volatile Fraction | F16: =F14*(2/100) -> 0.8 | G16: 0.7734 | I16: T100 | J16: 0.4919 | L16: T100 | M16: 0.666 | O16: T100 | P16: =G16+J16+M16 -> 1.9313 | Q16: ='01'!Q16+P16 -> 1.9313 | R16: =H16+K16+N16 -> 0
C17: Side Cut Fraction A | F17: =F14*12/100 -> 4.8 | G17: 0.227 | I17: T101 | J17: 0 | L17: T101 | M17: 0 | O17: T101 | P17: =G17+J17+M17 -> 0.227 | Q17: ='01'!Q17+P17 -> 0.227 | R17: =H17+K17+N17 -> 0
C18: Side Cut Fraction B | F18: - | G18: 4.93 | I18: T103 | J18: 14.098 | L18: T103 | M18: 14.062 | O18: T103 | P18: =G18+J18+M18 -> 33.09 | Q18: ='01'!Q18+P18 -> 33.09 | R18: =H18+K18+N18 -> 0
C19: Side Cut Fraction C | F19: - | P19: =G19+J19+M19 -> 0 | Q19: ='01'!Q19+P19 -> 0 | R19: =H19+K19+N19 -> 0
C20: Heavy Bottom Fraction | F20: - | G20: 0 | J20: 0 | M20: 0 | O20: colom | P20: =G20+J20+M20 -> 0 | Q20: ='01'!Q20+P20 -> 0 | R20: =H20+K20+N20 -> 0
C21: Organic Residue Stream | F21: =F14*(0.5/100) -> 0.2 | G21: 0.2381 | I21: T107 | J21: 0.4352 | L21: T107 | M21: 0.532 | O21: T107 | P21: =G21+J21+M21 -> 1.2053 | Q21: ='01'!Q21+P21 -> 1.2053 | R21: =H21+K21+N21 -> 0
A22: 102+ | C22: Feed Stream (C8-10 Process Input)) | F22: 24 | G22: 8.817 | I22: T24 | J22: 8.813 | L22: T24 | M22: 8.812 | O22: T24 | P22: =G22+J22+M22 -> 26.442 | Q22: ='01'!Q22+P22 -> 52.895 | R22: =H22+K22+N22 -> 0
C23: Hydrogenated Product Stream | F23: 24 | G23: 8.326 | I23: T112 | J23: 7.005 | L23: T112 | M23: 9.579 | O23: T112 | P23: =G23+J23+M23 -> 24.91 | Q23: ='01'!Q23+P23 -> 50.849 | R23: =H23+K23+N23 -> 0
A24: 103+ | C24: Light Hydrocarbon Fraction | F24: 24 | G24: 8.791 | I24: T112 | J24: 8.791 | L24: T112 | M24: 8.845 | O24: T112 | P24: =G24+J24+M24 -> 26.427 | Q24: ='01'!Q24+P24 -> 52.653 | R24: =H24+K24+N24 -> 0
C25: Light End (C6) | F25: - | G25: 0.1538 | I25: T117 | J25: 0.1537 | L25: T117 | M25: 0.152 | O25: T117 | P25: =G25+J25+M25 -> 0.4595 | Q25: ='01'!Q25+P25 -> 0.9214 | R25: =H25+K25+N25 -> 0
C26: Distillation Side Cut A | F26: - | G26: 8.351 | I26: T115 | J26: 8.35 | L26: T115 | M26: 8.352 | O26: T115 | P26: =G26+J26+M26 -> 25.053 | Q26: ='01'!Q26+P26 -> 49.931 | R26: =H26+K26+N26 -> 0
C27: Distillation Side Cut B | F27: - | G27: 0 | I27: colom | J27: 0 | L27: colom | M27: 0 | O27: colom | P27: =G27+J27+M27 -> 0 | Q27: ='01'!Q27+P27 -> 0 | R27: =H27+K27+N27 -> 0
C28: Heavy Residual Stream | F28: - | G28: 0.304 | I28: T119 | J28: 0.3051 | L28: T119 | M28: 0.306 | O28: T119 | P28: =G28+J28+M28 -> 0.9151 | Q28: ='01'!Q28+P28 -> 1.7981 | R28: =H28+K28+N28 -> 0
A29: 104 | C29: Feed Primary Stream (C8-10) | P29: =G29+J29+M29 -> 0 | Q29: ='01'!Q29+P29 -> 12.462 | R29: =H29+K29+N29 -> 0
C30: Feed Secondary Stream (Oleic Intermediate) | P30: =G30+J30+M30 -> 0 | Q30: ='01'!Q30+P30 -> 0 | R30: =H30+K30+N30 -> 0
C31: Feed Stream Auxiliary (Glycerol Phase) | P31: =G31+J31+M31 -> 0 | Q31: ='01'!Q31+P31 -> 2.467 | R31: =H31+K31+N31 -> 0
C32: Product Stream A (Medium Chain Ester) | I32: T129 | J32: 0.973 | L32: T129 | M32: 12.005 | O32: T129 | P32: =G32+J32+M32 -> 12.978 | Q32: ='01'!Q32+P32 -> 23.018 | R32: =H32+K32+N32 -> 0
C33: Product Stream B (Distilled Chemical Output) | P33: =G33+J33+M33 -> 0 | Q33: ='01'!Q33+P33 -> 0 | R33: =H33+K33+N33 -> 0

Sheet 03
A5: Operation Month | D5: ='01'!D5 -> February | E5: ='01'!E5 -> 2026
A6: Operation Date | D6: ='02'!D6+1 -> 46056
A8: I. Production
A9: Sect. | C9: Description | F9: Capacity | G9: Shift II (7:00 - 15:00) | I9: Storage | J9: Shift III (15:00 - 23:00) | L9: Storage | M9: Shift I (23:00 - 7:00) | O9: Storage | P9: To Day | Q9: MTD | R9: D. Time
F10: MT/Day | G10: Product | H10: D.Time | I10: 122T... | J10: Product | K10: D.Time | L10: 122T... | M10: Product | N10: D.Time | O10: 122T... | R10: Hours
A11: 101 | C11: Feed Stream (C16-18 Raw Ester) | F11: 60 | P11: =G11+J11+M11 -> 0 | Q11: =P11+'02'!Q11 -> 0 | R11: =H11+K11+N11 -> 0
C12: Oleic Intermediate Stream | F12: 30 | P12: =G12+J12+M12 -> 0 | Q12: =P12+'02'!Q12 -> 0 | R12: =H12+K12+N12 -> 0
C13: Heavy Phase Fraction | F13: 30 | P13: =G13+J13+M13 -> 0 | Q13: =P13+'02'!Q13 -> 0 | R13: =H13+K13+N13 -> 0
A14: 102 | C14: Feed Stream (Hydrogenated C16-18) | F14: 40 | G14: 13.106 | I14: T96 | J14: 12.907 | L14: T96 | M14: 13.509 | O14: T96 | P14: =G14+J14+M14 -> 39.522 | Q14: =P14+'02'!Q14 -> 77.232 | R14: =H14+K14+N14 -> 0
C15: Feed Stream (Hydrogenated Process Stock) | F15: 40 | P15: =G15+J15+M15 -> 0 | Q15: =P15+'02'!Q15 -> 0 | R15: =H15+K15+N15 -> 0
C16: Light Volatile Fraction | F16: =F14*(2/100) -> 0.8 | G16: 0.7996 | I16: T100 | J16: 1.135 | L16: T100 | M16: 1.155 | O16: T100 | P16: =G16+J16+M16 -> 3.0896 | Q16: =P16+'02'!Q16 -> 5.0209 | R16: =H16+K16+N16 -> 0
C17: Side Cut Fraction A | F17: =F14*12/100 -> 4.8 | G17: 0 | I17: T101 | J17: 0 | L17: T101 | M17: 0 | O17: T101 | P17: =G17+J17+M17 -> 0 | Q17: =P17+'02'!Q17 -> 0.227 | R17: =H17+K17+N17 -> 0
C18: Side Cut Fraction B | F18: - | G18: 11.797 | I18: T103 | J18: 11.911 | L18: T103 | M18: 11.441 | O18: T103 | P18: =G18+J18+M18 -> 35.149 | Q18: =P18+'02'!Q18 -> 68.239 | R18: =H18+K18+N18 -> 0
C19: Side Cut Fraction C | F19: - | P19: =G19+J19+M19 -> 0 | Q19: =P19+'02'!Q19 -> 0 | R19: =H19+K19+N19 -> 0
C20: Heavy Bottom Fraction | F20: - | P20: =G20+J20+M20 -> 0 | Q20: =P20+'02'!Q20 -> 0 | R20: =H20+K20+N20 -> 0
C21: Organic Residue Stream | F21: =F14*(0.5/100) -> 0.2 | G21: 0.4901 | I21: T107 | J21: 0.438 | L21: T107 | M21: 0.354 | O21: T107 | P21: =G21+J21+M21 -> 1.2821 | Q21: =P21+'02'!Q21 -> 2.4874 | R21: =H21+K21+N21 -> 0
A22: 102+ | C22: Feed Stream (C8-10 Process Input)) | F22: 24 | G22: 8.821 | I22: T24 | J22: 8.814 | L22: T24 | M22: 8.538 | O22: T24 | P22: =G22+J22+M22 -> 26.173 | Q22: =P22+'02'!Q22 -> 79.068 | R22: =H22+K22+N22 -> 0
C23: Hydrogenated Product Stream | F23: 24 | G23: 7.458 | I23: T112 | J23: 7.913 | L23: T112 | M23: 9.138 | O23: T112 | P23: =G23+J23+M23 -> 24.509 | Q23: =P23+'02'!Q23 -> 75.358 | R23: =H23+K23+N23 -> 0
A24: 103+ | C24: Light Hydrocarbon Fraction | F24: 24 | G24: 8.792 | I24: T112 | J24: 8.828 | L24: T112 | M24: 8.811 | O24: T112 | P24: =G24+J24+M24 -> 26.431 | Q24: =P24+'02'!Q24 -> 79.084 | R24: =H24+K24+N24 -> 0
C25: Light End (C6) | F25: - | G25: 0.1531 | I25: T117 | J25: 0.153 | L25: T117 | M25: 0.152 | O25: T117 | P25: =G25+J25+M25 -> 0.4581 | Q25: =P25+'02'!Q25 -> 1.3795 | R25: =H25+K25+N25 -> 0
C26: Distillation Side Cut A | F26: - | G26: 8.35 | I26: T115 | J26: 8.351 | L26: T115 | M26: 8.351 | O26: T115 | P26: =G26+J26+M26 -> 25.052 | Q26: =P26+'02'!Q26 -> 74.983 | R26: =H26+K26+N26 -> 0
C27: Distillation Side Cut B | F27: - | G27: 0 | I27: colom | J27: 0 | L27: colom | M27: 0 | O27: colom | P27: =G27+J27+M27 -> 0 | Q27: =P27+'02'!Q27 -> 0 | R27: =H27+K27+N27 -> 0
C28: Heavy Residual Stream | F28: - | G28: 0.3049 | I28: T119 | J28: 0.304 | L28: T119 | M28: 0.306 | O28: T119 | P28: =G28+J28+M28 -> 0.9149 | Q28: =P28+'02'!Q28 -> 2.713 | R28: =H28+K28+N28 -> 0
A29: 104 | C29: Feed Primary Stream (C8-10) | G29: 12.404 | I29: T120 | P29: =G29+J29+M29 -> 12.404 | Q29: =P29+'02'!Q29 -> 24.866 | R29: =H29+K29+N29 -> 0
C30: Feed Secondary Stream (Oleic Intermediate) | P30: =G30+J30+M30 -> 0 | Q30: =P30+'02'!Q30 -> 0 | R30: =H30+K30+N30 -> 0
C31: Feed Stream Auxiliary (Glycerol Phase) | G31: 2.464 | I31: T124 | P31: =G31+J31+M31 -> 2.464 | Q31: =P31+'02'!Q31 -> 4.931 | R31: =H31+K31+N31 -> 0
C32: Product Stream A (Medium Chain Ester) | M32: 0.919 | O32: T129 | P32: =G32+J32+M32 -> 0.919 | Q32: =P32+'02'!Q32 -> 23.937 | R32: =H32+K32+N32 -> 0
C33: Product Stream B (Distilled Chemical Output) | P33: =G33+J33+M33 -> 0 | Q33: =P33+'02'!Q33 -> 0 | R33: =H33+K33+N33 -> 0

Sheet 04
A5: Operation Month | D5: ='01'!D5 -> February | E5: ='01'!E5 -> 2026
A6: Operation Date | D6: ='03'!D6+1 -> 46057
A8: I. Production
A9: Sect. | C9: Description | F9: Capacity | G9: Shift II (7:00 - 15:00) | I9: Storage | J9: Shift III (15:00 - 23:00) | L9: Storage | M9: Shift I (23:00 - 7:00) | O9: Storage | P9: To Day | Q9: MTD | R9: D. Time
F10: MT/Day | G10: Product | H10: D.Time | I10: 122T... | J10: Product | K10: D.Time | L10: 122T... | M10: Product | N10: D.Time | O10: 122T... | R10: Hours
A11: 101 | C11: Feed Stream (C16-18 Raw Ester) | F11: 60 | G11: 8 | I11: T34 | J11: 24.9 | L11: T34 | M11: 19.8 | O11: T34 | P11: =G11+J11+M11 -> 52.7 | Q11: =P11+'03'!Q11 -> 52.7 | R11: =H11+K11+N11 -> 0
C12: Oleic Intermediate Stream | F12: 30 | M12: 11.2 | O12: T94/T95 | P12: =G12+J12+M12 -> 11.2 | Q12: =P12+'03'!Q12 -> 11.2 | R12: =H12+K12+N12 -> 0
C13: Heavy Phase Fraction | F13: 30 | P13: =G13+J13+M13 -> 0 | Q13: =P13+'03'!Q13 -> 0 | R13: =H13+K13+N13 -> 0
A14: 102 | C14: Feed Stream (Hydrogenated C16-18) | F14: 40 | G14: 13.686 | I14: T96 | J14: 12.192 | L14: T96 | M14: 13.549 | O14: T96 | P14: =G14+J14+M14 -> 39.427 | Q14: =P14+'03'!Q14 -> 116.659 | R14: =H14+K14+N14 -> 0
C15: Feed Stream (Hydrogenated Process Stock) | F15: 40 | P15: =G15+J15+M15 -> 0 | Q15: =P15+'03'!Q15 -> 0 | R15: =H15+K15+N15 -> 0
C16: Light Volatile Fraction | F16: =F14*(2/100) -> 0.8 | G16: 1.1883 | I16: T100 | J16: 1.069 | L16: T100 | M16: 1.161 | O16: T100 | P16: =G16+J16+M16 -> 3.4183 | Q16: =P16+'03'!Q16 -> 8.4392 | R16: =H16+K16+N16 -> 0
C17: Side Cut Fraction A | F17: =F14*12/100 -> 4.8 | P17: =G17+J17+M17 -> 0 | Q17: =P17+'03'!Q17 -> 0.227 | R17: =H17+K17+N17 -> 0
C18: Side Cut Fraction B | F18: - | G18: 12.299 | I18: T103 | J18: 10.513 | L18: T103 | M18: 11.681 | O18: T103 | P18: =G18+J18+M18 -> 34.493 | Q18: =P18+'03'!Q18 -> 102.732 | R18: =H18+K18+N18 -> 0
C19: Side Cut Fraction C | F19: - | P19: =G19+J19+M19 -> 0 | Q19: =P19+'03'!Q19 -> 0 | R19: =H19+K19+N19 -> 0
C20: Heavy Bottom Fraction | F20: - | P20: =G20+J20+M20 -> 0 | Q20: =P20+'03'!Q20 -> 0 | R20: =H20+K20+N20 -> 0
C21: Organic Residue Stream | F21: =F14*(0.5/100) -> 0.2 | G21: 0.4105 | I21: T107 | J21: 0.404 | L21: T107 | M21: 0.444 | O21: T107 | P21: =G21+J21+M21 -> 1.2585 | Q21: =P21+'03'!Q21 -> 3.7459 | R21: =H21+K21+N21 -> 0
A22: 102+ | C22: Feed Stream (C8-10 Process Input)) | F22: 24 | G22: 0.277 | I22: T24 | P22: =G22+J22+M22 -> 0.277 | Q22: =P22+'03'!Q22 -> 79.345 | R22: =H22+K22+N22 -> 0
C23: Hydrogenated Product Stream | F23: 24 | G23: 6.307 | I23: T112 | P23: =G23+J23+M23 -> 6.307 | Q23: =P23+'03'!Q23 -> 81.665 | R23: =H23+K23+N23 -> 0
A24: 103+ | C24: Light Hydrocarbon Fraction | F24: 24 | G24: 8.792 | I24: T112 | J24: 8.792 | L24: T112 | M24: 8.811 | O24: T112 | P24: =G24+J24+M24 -> 26.395 | Q24: =P24+'03'!Q24 -> 105.479 | R24: =H24+K24+N24 -> 0
C25: Light End (C6) | F25: - | G25: 0.1533 | I25: T117 | J25: 0.153 | L25: T117 | M25: 0.153 | O25: T117 | P25: =G25+J25+M25 -> 0.4593 | Q25: =P25+'03'!Q25 -> 1.8388 | R25: =H25+K25+N25 -> 0
C26: Distillation Side Cut A | F26: - | G26: 8.35 | I26: T115 | J26: 8.352 | L26: T115 | M26: 8.35 | O26: T115 | P26: =G26+J26+M26 -> 25.052 | Q26: =P26+'03'!Q26 -> 100.035 | R26: =H26+K26+N26 -> 0
C27: Distillation Side Cut B | F27: - | G27: 0 | I27: colom | J27: 0 | L27: colom | M27: 0 | O27: colom | P27: =G27+J27+M27 -> 0 | Q27: =P27+'03'!Q27 -> 0 | R27: =H27+K27+N27 -> 0
C28: Heavy Residual Stream | F28: - | G28: 0.3056 | I28: T119 | J28: 0.304 | L28: T119 | M28: 0.306 | O28: T119 | P28: =G28+J28+M28 -> 0.9156 | Q28: =P28+'03'!Q28 -> 3.6286 | R28: =H28+K28+N28 -> 0
A29: 104 | C29: Feed Primary Stream (C8-10) | J29: 12.182 | L29: T120 | P29: =G29+J29+M29 -> 12.182 | Q29: =P29+'03'!Q29 -> 37.048 | R29: =H29+K29+N29 -> 0
C30: Feed Secondary Stream (Oleic Intermediate) | P30: =G30+J30+M30 -> 0 | Q30: =P30+'03'!Q30 -> 0 | R30: =H30+K30+N30 -> 0
C31: Feed Stream Auxiliary (Glycerol Phase) | J31: 2.47 | L31: T124 | P31: =G31+J31+M31 -> 2.47 | Q31: =P31+'03'!Q31 -> 7.401 | R31: =H31+K31+N31 -> 0
C32: Product Stream A (Medium Chain Ester) | G32: 12.063 | I32: T129 | P32: =G32+J32+M32 -> 12.063 | Q32: =P32+'03'!Q32 -> 36 | R32: =H32+K32+N32 -> 0
C33: Product Stream B (Distilled Chemical Output) | P33: =G33+J33+M33 -> 0 | Q33: =P33+'03'!Q33 -> 0 | R33: =H33+K33+N33 -> 0

Sheet 05
A5: Operation Month | D5: ='01'!D5 -> February | E5: ='01'!E5 -> 2026
A6: Operation Date | D6: ='04'!D6+1 -> 46058
A8: I. Production
A9: Sect. | C9: Description | F9: Capacity | G9: Shift II (7:00 - 15:00) | I9: Storage | J9: Shift III (15:00 - 23:00) | L9: Storage | M9: Shift I (23:00 - 7:00) | O9: Storage | P9: To Day | Q9: MTD | R9: D. Time
F10: MT/Day | G10: Product | H10: D.Time | I10: 122T... | J10: Product | K10: D.Time | L10: 122T... | M10: Product | N10: D.Time | O10: 122T... | R10: Hours
A11: 101 | C11: Feed Stream (C16-18 Raw Ester) | F11: 60 | G11: 19.9 | I11: T34 | J11: 23.6 | L11: T34 | M11: 17.2 | O11: T34 | P11: =G11+J11+M11 -> 60.7 | Q11: =P11+'04'!Q11 -> 113.4 | R11: =H11+K11+N11 -> 0
C12: Oleic Intermediate Stream | F12: 30 | G12: 10.1 | I12: T94 | J12: 13.4 | L12: T94 | M12: 9 | O12: T94 | P12: =G12+J12+M12 -> 32.5 | Q12: =P12+'04'!Q12 -> 43.7 | R12: =H12+K12+N12 -> 0
C13: Heavy Phase Fraction | F13: 30 | G13: 8.9 | I13: T99 | J13: 13.5 | L13: T99 | M13: 7.3 | O13: T99 | P13: =G13+J13+M13 -> 29.7 | Q13: =P13+'04'!Q13 -> 29.7 | R13: =H13+K13+N13 -> 0
A14: 102 | C14: Feed Stream (Hydrogenated C16-18) | F14: 40 | G14: 6.437 | I14: T96 | J14: 0.416 | L14: T96 | M14: 8.584 | O14: T96 | P14: =G14+J14+M14 -> 15.437 | Q14: =P14+'04'!Q14 -> 132.096 | R14: =H14+K14+N14 -> 0
C15: Feed Stream (Hydrogenated Process Stock) | F15: 40 | P15: =G15+J15+M15 -> 0 | Q15: =P15+'04'!Q15 -> 0 | R15: =H15+K15+N15 -> 0
C16: Light Volatile Fraction | F16: =F14*(2/100) -> 0.8 | G16: 0.737 | I16: 102 | J16: 0.0382 | L16: T102 | M16: 0.8809 | O16: T102 | P16: =G16+J16+M16 -> 1.6561 | Q16: =P16+'04'!Q16 -> 10.0953 | R16: =H16+K16+N16 -> 0
C17: Side Cut Fraction A | F17: =F14*12/100 -> 4.8 | P17: =G17+J17+M17 -> 0 | Q17: =P17+'04'!Q17 -> 0.227 | R17: =H17+K17+N17 -> 0
C18: Side Cut Fraction B | F18: - | P18: =G18+J18+M18 -> 0 | Q18: =P18+'04'!Q18 -> 102.732 | R18: =H18+K18+N18 -> 0
C19: Side Cut Fraction C | F19: - | G19: 6.32 | I19: T103 | J19: 0.272 | L19: T103 | M19: 7.121 | O19: T103 | P19: =G19+J19+M19 -> 13.713 | Q19: =P19+'04'!Q19 -> 13.713 | R19: =H19+K19+N19 -> 0
C20: Heavy Bottom Fraction | F20: - | J20: 0.37 | L20: T106 | M20: 0.436 | O20: T106 | P20: =G20+J20+M20 -> 0.806 | Q20: =P20+'04'!Q20 -> 0.806 | R20: =H20+K20+N20 -> 0
C21: Organic Residue Stream | F21: =F14*(0.5/100) -> 0.2 | G21: 0.4001 | I21: T107 | J21: 0.015 | L21: T107 | M21: 0.3379 | O21: T107 | P21: =G21+J21+M21 -> 0.753 | Q21: =P21+'04'!Q21 -> 4.4989 | R21: =H21+K21+N21 -> 0
A22: 102+ | C22: Feed Stream (C8-10 Process Input)) | F22: 24 | P22: =G22+J22+M22 -> 0 | Q22: =P22+'04'!Q22 -> 79.345 | R22: =H22+K22+N22 -> 0
C23: Hydrogenated Product Stream | F23: 24 | P23: =G23+J23+M23 -> 0 | Q23: =P23+'04'!Q23 -> 81.665 | R23: =H23+K23+N23 -> 0
A24: 103+ | C24: Light Hydrocarbon Fraction | F24: 24 | P24: =G24+J24+M24 -> 0 | Q24: =P24+'04'!Q24 -> 105.479 | R24: =H24+K24+N24 -> 0
C25: Light End (C6) | F25: - | P25: =G25+J25+M25 -> 0 | Q25: =P25+'04'!Q25 -> 1.8388 | R25: =H25+K25+N25 -> 0
C26: Distillation Side Cut A | F26: - | P26: =G26+J26+M26 -> 0 | Q26: =P26+'04'!Q26 -> 100.035 | R26: =H26+K26+N26 -> 0
C27: Distillation Side Cut B | F27: - | P27: =G27+J27+M27 -> 0 | Q27: =P27+'04'!Q27 -> 0 | R27: =H27+K27+N27 -> 0
C28: Heavy Residual Stream | F28: - | P28: =G28+J28+M28 -> 0 | Q28: =P28+'04'!Q28 -> 3.6286 | R28: =H28+K28+N28 -> 0
A29: 104 | C29: Feed Primary Stream (C8-10) | M29: 12.35 | O29: T120 | P29: =G29+J29+M29 -> 12.35 | Q29: =P29+'04'!Q29 -> 49.398 | R29: =H29+K29+N29 -> 0
C30: Feed Secondary Stream (Oleic Intermediate) | P30: =G30+J30+M30 -> 0 | Q30: =P30+'04'!Q30 -> 0 | R30: =H30+K30+N30 -> 0
C31: Feed Stream Auxiliary (Glycerol Phase) | M31: 2.468 | O31: T124 | P31: =G31+J31+M31 -> 2.468 | Q31: =P31+'04'!Q31 -> 9.869 | R31: =H31+K31+N31 -> 0
C32: Product Stream A (Medium Chain Ester) | J32: 9.136 | L32: T128 | M32: 3.686 | O32: T128 | P32: =G32+J32+M32 -> 12.822 | Q32: =P32+'04'!Q32 -> 48.822 | R32: =H32+K32+N32 -> 0
C33: Product Stream B (Distilled Chemical Output) | P33: =G33+J33+M33 -> 0 | Q33: =P33+'04'!Q33 -> 0 | R33: =H33+K33+N33 -> 0

Sheet 06
A5: Operation Month | D5: ='01'!D5 -> February | E5: ='01'!E5 -> 2026
A6: Operation Date | D6: ='05'!D6+1 -> 46059
A8: I. Production
A9: Sect. | C9: Description | F9: Capacity | G9: Shift II (7:00 - 15:00) | I9: Storage | J9: Shift III (15:00 - 23:00) | L9: Storage | M9: Shift I (23:00 - 7:00) | O9: Storage | P9: To Day | Q9: MTD | R9: D. Time
F10: MT/Day | G10: Product | H10: D.Time | I10: 122T... | J10: Product | K10: D.Time | L10: 122T... | M10: Product | N10: D.Time | O10: 122T... | R10: Hours
A11: 101 | C11: Feed Stream (C16-18 Raw Ester) | F11: 60 | G11: 15.8 | I11: T34 | J11: 22 | L11: T34 | M11: 22.7 | O11: T34 | P11: =G11+J11+M11 -> 60.5 | Q11: =P11+'05'!Q11 -> 173.9 | R11: =H11+K11+N11 -> 0
C12: Oleic Intermediate Stream | F12: 30 | G12: 10.5 | I12: T94 | J12: 10.4 | L12: T94 | M12: 13.1 | O12: T94 | P12: =G12+J12+M12 -> 34 | Q12: =P12+'05'!Q12 -> 77.7 | R12: =H12+K12+N12 -> 0
C13: Heavy Phase Fraction | F13: 30 | G13: 7.7 | I13: T99 | J13: 10.7 | L13: T99 | M13: 8.7 | O13: T99 | P13: =G13+J13+M13 -> 27.1 | Q13: =P13+'05'!Q13 -> 56.8 | R13: =H13+K13+N13 -> 0
A14: 102 | C14: Feed Stream (Hydrogenated C16-18) | F14: 40 | G14: 6.184 | I14: T96 | J14: 8.173 | L14: T96 | M14: 7.668 | O14: T96 | P14: =G14+J14+M14 -> 22.025 | Q14: =P14+'05'!Q14 -> 154.121 | R14: =H14+K14+N14 -> 0
C15: Feed Stream (Hydrogenated Process Stock) | F15: 40 | P15: =G15+J15+M15 -> 0 | Q15: =P15+'05'!Q15 -> 0 | R15: =H15+K15+N15 -> 0
C16: Light Volatile Fraction | F16: =F14*(2/100) -> 0.8 | G16: 0.783 | I16: 100 | J16: 0.734 | L16: 100 | M16: 0.693 | O16: 100 | P16: =G16+J16+M16 -> 2.21 | Q16: =P16+'05'!Q16 -> 12.3053 | R16: =H16+K16+N16 -> 0
C17: Side Cut Fraction A | F17: =F14*12/100 -> 4.8 | P17: =G17+J17+M17 -> 0 | Q17: =P17+'05'!Q17 -> 0.227 | R17: =H17+K17+N17 -> 0
C18: Side Cut Fraction B | F18: - | P18: =G18+J18+M18 -> 0 | Q18: =P18+'05'!Q18 -> 102.732 | R18: =H18+K18+N18 -> 0
C19: Side Cut Fraction C | F19: - | G19: 4.248 | I19: T101 | J19: 6.087 | L19: T101 | M19: 6.128 | O19: T101 | P19: =G19+J19+M19 -> 16.463 | Q19: =P19+'05'!Q19 -> 30.176 | R19: =H19+K19+N19 -> 0
C20: Heavy Bottom Fraction | F20: - | P20: =G20+J20+M20 -> 0 | Q20: =P20+'05'!Q20 -> 0.806 | R20: =H20+K20+N20 -> 0
C21: Organic Residue Stream | F21: =F14*(0.5/100) -> 0.2 | G21: 0.4217 | I21: T107 | J21: 1.315 | L21: T107 | M21: 0.9213 | O21: T107 | P21: =G21+J21+M21 -> 2.658 | Q21: =P21+'05'!Q21 -> 7.1569 | R21: =H21+K21+N21 -> 0
A22: 102+ | C22: Feed Stream (C8-10 Process Input)) | F22: 24 | P22: =G22+J22+M22 -> 0 | Q22: =P22+'05'!Q22 -> 79.345 | R22: =H22+K22+N22 -> 0
C23: Hydrogenated Product Stream | F23: 24 | P23: =G23+J23+M23 -> 0 | Q23: =P23+'05'!Q23 -> 81.665 | R23: =H23+K23+N23 -> 0
A24: 103+ | C24: Light Hydrocarbon Fraction | F24: 24 | P24: =G24+J24+M24 -> 0 | Q24: =P24+'05'!Q24 -> 105.479 | R24: =H24+K24+N24 -> 0
C25: Light End (C6) | F25: - | P25: =G25+J25+M25 -> 0 | Q25: =P25+'05'!Q25 -> 1.8388 | R25: =H25+K25+N25 -> 0
C26: Distillation Side Cut A | F26: - | P26: =G26+J26+M26 -> 0 | Q26: =P26+'05'!Q26 -> 100.035 | R26: =H26+K26+N26 -> 0
C27: Distillation Side Cut B | F27: - | P27: =G27+J27+M27 -> 0 | Q27: =P27+'05'!Q27 -> 0 | R27: =H27+K27+N27 -> 0
C28: Heavy Residual Stream | F28: - | P28: =G28+J28+M28 -> 0 | Q28: =P28+'05'!Q28 -> 3.6286 | R28: =H28+K28+N28 -> 0
A29: 104 | C29: Feed Primary Stream (C8-10) | P29: =G29+J29+M29 -> 0 | Q29: =P29+'05'!Q29 -> 49.398 | R29: =H29+K29+N29 -> 0
C30: Feed Secondary Stream (Oleic Intermediate) | P30: =G30+J30+M30 -> 0 | Q30: =P30+'05'!Q30 -> 0 | R30: =H30+K30+N30 -> 0
C31: Feed Stream Auxiliary (Glycerol Phase) | P31: =G31+J31+M31 -> 0 | Q31: =P31+'05'!Q31 -> 9.869 | R31: =H31+K31+N31 -> 0
C32: Product Stream A (Medium Chain Ester) | J32: 1.551 | L32: T128 | M32: 11.378 | O32: T128 | P32: =G32+J32+M32 -> 12.929 | Q32: =P32+'05'!Q32 -> 61.751 | R32: =H32+K32+N32 -> 0
C33: Product Stream B (Distilled Chemical Output) | P33: =G33+J33+M33 -> 0 | Q33: =P33+'05'!Q33 -> 0 | R33: =H33+K33+N33 -> 0

Sheet 07
A5: Operation Month | D5: ='01'!D5 -> February | E5: ='01'!E5 -> 2026
A6: Operation Date | D6: ='06'!D6+1 -> 46060
A8: I. Production
A9: Sect. | C9: Description | F9: Capacity | G9: Shift II (7:00 - 15:00) | I9: Storage | J9: Shift III (15:00 - 23:00) | L9: Storage | M9: Shift I (23:00 - 7:00) | O9: Storage | P9: To Day | Q9: MTD | R9: D. Time
F10: MT/Day | G10: Product | H10: D.Time | I10: 122T... | J10: Product | K10: D.Time | L10: 122T... | M10: Product | N10: D.Time | O10: 122T... | R10: Hours
A11: 101 | C11: Feed Stream (C16-18 Raw Ester) | F11: 60 | G11: 16.3 | I11: T34 | J11: 22.3 | L11: T34 | M11: 23.1 | O11: T34 | P11: =G11+J11+M11 -> 61.7 | Q11: =P11+'06'!Q11 -> 235.6 | R11: =H11+K11+N11 -> 0
C12: Oleic Intermediate Stream | F12: 30 | G12: 10.5 | I12: T94 | J12: 11.1 | L12: T94 | M12: 12.5 | O12: T94/T95 | P12: =G12+J12+M12 -> 34.1 | Q12: =P12+'06'!Q12 -> 111.8 | R12: =H12+K12+N12 -> 0
C13: Heavy Phase Fraction | F13: 30 | G13: 9.9 | I13: T99 | J13: 10.2 | L13: T99 | M13: 7.4 | O13: T99 | P13: =G13+J13+M13 -> 27.5 | Q13: =P13+'06'!Q13 -> 84.3 | R13: =H13+K13+N13 -> 0
A14: 102 | C14: Feed Stream (Hydrogenated C16-18) | F14: 40 | G14: 4.773 | I14: T96 | P14: =G14+J14+M14 -> 4.773 | Q14: =P14+'06'!Q14 -> 158.894 | R14: =H14+K14+N14 -> 0
C15: Feed Stream (Hydrogenated Process Stock) | F15: 40 | P15: =G15+J15+M15 -> 0 | Q15: =P15+'06'!Q15 -> 0 | R15: =H15+K15+N15 -> 0
C16: Light Volatile Fraction | F16: =F14*(2/100) -> 0.8 | G16: 0.5734 | I16: 100 | P16: =G16+J16+M16 -> 0.5734 | Q16: =P16+'06'!Q16 -> 12.8787 | R16: =H16+K16+N16 -> 0
C17: Side Cut Fraction A | F17: =F14*12/100 -> 4.8 | P17: =G17+J17+M17 -> 0 | Q17: =P17+'06'!Q17 -> 0.227 | R17: =H17+K17+N17 -> 0
C18: Side Cut Fraction B | F18: - | P18: =G18+J18+M18 -> 0 | Q18: =P18+'06'!Q18 -> 102.732 | R18: =H18+K18+N18 -> 0
C19: Side Cut Fraction C | F19: - | G19: 4.293 | I19: T101 | P19: =G19+J19+M19 -> 4.293 | Q19: =P19+'06'!Q19 -> 34.469 | R19: =H19+K19+N19 -> 0
C20: Heavy Bottom Fraction | F20: - | P20: =G20+J20+M20 -> 0 | Q20: =P20+'06'!Q20 -> 0.806 | R20: =H20+K20+N20 -> 0
C21: Organic Residue Stream | F21: =F14*(0.5/100) -> 0.2 | G21: 0.681 | I21: T107 | P21: =G21+J21+M21 -> 0.681 | Q21: =P21+'06'!Q21 -> 7.8379 | R21: =H21+K21+N21 -> 0
A22: 102+ | C22: Feed Stream (C8-10 Process Input)) | F22: 24 | P22: =G22+J22+M22 -> 0 | Q22: =P22+'06'!Q22 -> 79.345 | R22: =H22+K22+N22 -> 0
C23: Hydrogenated Product Stream | F23: 24 | P23: =G23+J23+M23 -> 0 | Q23: =P23+'06'!Q23 -> 81.665 | R23: =H23+K23+N23 -> 0
A24: 103+ | C24: Light Hydrocarbon Fraction | F24: 24 | G24: 0 | I24: T119 | J24: 0.996 | L24: T119 | M24: 7.393 | O24: T119 | P24: =G24+J24+M24 -> 8.389 | Q24: =P24+'06'!Q24 -> 113.868 | R24: =H24+K24+N24 -> 0
C25: Light End (C6) | F25: - | G25: 0 | I25: T117 | J25: 0.74 | L25: T117 | M25: 0.5249 | O25: T117 | P25: =G25+J25+M25 -> 1.2649 | Q25: =P25+'06'!Q25 -> 3.1037 | R25: =H25+K25+N25 -> 0
C26: Distillation Side Cut A | F26: - | G26: 0 | I26: T117 | J26: 0.865 | L26: T117 | M26: 6.077 | O26: T117 | P26: =G26+J26+M26 -> 6.942 | Q26: =P26+'06'!Q26 -> 106.977 | R26: =H26+K26+N26 -> 0
C27: Distillation Side Cut B | F27: - | P27: =G27+J27+M27 -> 0 | Q27: =P27+'06'!Q27 -> 0 | R27: =H27+K27+N27 -> 0
C28: Heavy Residual Stream | F28: - | G28: 0 | I28: T107 | J28: 0.121 | L28: T107 | M28: 0.8578 | O28: T107 | P28: =G28+J28+M28 -> 0.9788 | Q28: =P28+'06'!Q28 -> 4.6074 | R28: =H28+K28+N28 -> 0
A29: 104 | C29: Feed Primary Stream (C8-10) | G29: 12.413 | I29: T120 | P29: =G29+J29+M29 -> 12.413 | Q29: =P29+'06'!Q29 -> 61.811 | R29: =H29+K29+N29 -> 0
C30: Feed Secondary Stream (Oleic Intermediate) | P30: =G30+J30+M30 -> 0 | Q30: =P30+'06'!Q30 -> 0 | R30: =H30+K30+N30 -> 0
C31: Feed Stream Auxiliary (Glycerol Phase) | G31: 2.468 | I31: T124 | P31: =G31+J31+M31 -> 2.468 | Q31: =P31+'06'!Q31 -> 12.337 | R31: =H31+K31+N31 -> 0
C32: Product Stream A (Medium Chain Ester) | M32: 1.332 | O32: T127 | P32: =G32+J32+M32 -> 1.332 | Q32: =P32+'06'!Q32 -> 63.083 | R32: =H32+K32+N32 -> 0
C33: Product Stream B (Distilled Chemical Output) | P33: =G33+J33+M33 -> 0 | Q33: =P33+'06'!Q33 -> 0 | R33: =H33+K33+N33 -> 0

Sheet 08
A5: Operation Month | D5: ='01'!D5 -> February | E5: ='01'!E5 -> 2026
A6: Operation Date | D6: ='07'!D6+1 -> 46061
A8: I. Production
A9: Sect. | C9: Description | F9: Capacity | G9: Shift II (7:00 - 15:00) | I9: Storage | J9: Shift III (15:00 - 23:00) | L9: Storage | M9: Shift I (23:00 - 7:00) | O9: Storage | P9: To Day | Q9: MTD | R9: D. Time
F10: MT/Day | G10: Product | H10: D.Time | I10: 122T... | J10: Product | K10: D.Time | L10: 122T... | M10: Product | N10: D.Time | O10: 122T... | R10: Hours
A11: 101 | C11: Feed Stream (C16-18 Raw Ester) | F11: 60 | G11: 15.2 | I11: T34 | J11: 23.1 | L11: T34 | M11: 22.1 | O11: T34 | P11: =G11+J11+M11 -> 60.4 | Q11: =P11+'07'!Q11 -> 296 | R11: =H11+K11+N11 -> 0
C12: Oleic Intermediate Stream | F12: 30 | G12: 8.8 | I12: T94/T95 | J12: 10.8 | L12: T94 | M12: 14.6 | O12: T94 | P12: =G12+J12+M12 -> 34.2 | Q12: =P12+'07'!Q12 -> 146 | R12: =H12+K12+N12 -> 0
C13: Heavy Phase Fraction | F13: 30 | G13: 8.9 | I13: T99 | J13: 8.7 | L13: T99 | M13: 10.1 | O13: T99 | P13: =G13+J13+M13 -> 27.7 | Q13: =P13+'07'!Q13 -> 112 | R13: =H13+K13+N13 -> 0
A14: 102 | C14: Feed Stream (Hydrogenated C16-18) | F14: 40 | P14: =G14+J14+M14 -> 0 | Q14: =P14+'07'!Q14 -> 158.894 | R14: =H14+K14+N14 -> 0
C15: Feed Stream (Hydrogenated Process Stock) | F15: 40 | P15: =G15+J15+M15 -> 0 | Q15: =P15+'07'!Q15 -> 0 | R15: =H15+K15+N15 -> 0
C16: Light Volatile Fraction | F16: =F14*(2/100) -> 0.8 | P16: =G16+J16+M16 -> 0 | Q16: =P16+'07'!Q16 -> 12.8787 | R16: =H16+K16+N16 -> 0
C17: Side Cut Fraction A | F17: =F14*12/100 -> 4.8 | P17: =G17+J17+M17 -> 0 | Q17: =P17+'07'!Q17 -> 0.227 | R17: =H17+K17+N17 -> 0
C18: Side Cut Fraction B | F18: - | P18: =G18+J18+M18 -> 0 | Q18: =P18+'07'!Q18 -> 102.732 | R18: =H18+K18+N18 -> 0
C19: Side Cut Fraction C | F19: - | P19: =G19+J19+M19 -> 0 | Q19: =P19+'07'!Q19 -> 34.469 | R19: =H19+K19+N19 -> 0
C20: Heavy Bottom Fraction | F20: - | P20: =G20+J20+M20 -> 0 | Q20: =P20+'07'!Q20 -> 0.806 | R20: =H20+K20+N20 -> 0
C21: Organic Residue Stream | F21: =F14*(0.5/100) -> 0.2 | P21: =G21+J21+M21 -> 0 | Q21: =P21+'07'!Q21 -> 7.8379 | R21: =H21+K21+N21 -> 0
A22: 102+ | C22: Feed Stream (C8-10 Process Input)) | F22: 24 | P22: =G22+J22+M22 -> 0 | Q22: =P22+'07'!Q22 -> 79.345 | R22: =H22+K22+N22 -> 0
C23: Hydrogenated Product Stream | F23: 24 | P23: =G23+J23+M23 -> 0 | Q23: =P23+'07'!Q23 -> 81.665 | R23: =H23+K23+N23 -> 0
A24: 103+ | C24: Light Hydrocarbon Fraction | F24: 24 | G24: 5.316 | I24: T119 | J24: 5.685 | L24: T114 | M24: 7.226 | O24: T114 | P24: =G24+J24+M24 -> 18.227 | Q24: =P24+'07'!Q24 -> 132.095 | R24: =H24+K24+N24 -> 0
C25: Light End (C6) | F25: - | G25: 0.3981 | I25: T117 | J25: 0.215 | L25: T117 | M25: 0.2468 | O25: T117 | P25: =G25+J25+M25 -> 0.8599 | Q25: =P25+'07'!Q25 -> 3.9636 | R25: =H25+K25+N25 -> 0
C26: Distillation Side Cut A | F26: - | G26: 4.363 | I26: T117 | J26: 4.962 | L26: T117 | M26: 6.428 | O26: T117 | P26: =G26+J26+M26 -> 15.753 | Q26: =P26+'07'!Q26 -> 122.73 | R26: =H26+K26+N26 -> 0
C27: Distillation Side Cut B | F27: - | P27: =G27+J27+M27 -> 0 | Q27: =P27+'07'!Q27 -> 0 | R27: =H27+K27+N27 -> 0
C28: Heavy Residual Stream | F28: - | G28: 0.6367 | I28: T107 | J28: 0.635 | L28: T107 | M28: 0.5275 | O28: T107 | P28: =G28+J28+M28 -> 1.7992 | Q28: =P28+'07'!Q28 -> 6.4066 | R28: =H28+K28+N28 -> 0
A29: 104 | C29: Feed Primary Stream (C8-10) | J29: 12.584 | L29: T120 | P29: =G29+J29+M29 -> 12.584 | Q29: =P29+'07'!Q29 -> 74.395 | R29: =H29+K29+N29 -> 0
C30: Feed Secondary Stream (Oleic Intermediate) | P30: =G30+J30+M30 -> 0 | Q30: =P30+'07'!Q30 -> 0 | R30: =H30+K30+N30 -> 0
C31: Feed Stream Auxiliary (Glycerol Phase) | J31: 2.463 | L31: T124 | P31: =G31+J31+M31 -> 2.463 | Q31: =P31+'07'!Q31 -> 14.8 | R31: =H31+K31+N31 -> 0
C32: Product Stream A (Medium Chain Ester) | G32: 11.291 | I32: T127 | P32: =G32+J32+M32 -> 11.291 | Q32: =P32+'07'!Q32 -> 74.374 | R32: =H32+K32+N32 -> 0
C33: Product Stream B (Distilled Chemical Output) | P33: =G33+J33+M33 -> 0 | Q33: =P33+'07'!Q33 -> 0 | R33: =H33+K33+N33 -> 0

Sheet 09
A5: Operation Month | D5: ='01'!D5 -> February | E5: ='01'!E5 -> 2026
A6: Operation Date | D6: ='08'!D6+1 -> 46062
A8: I. Production
A9: Sect. | C9: Description | F9: Capacity | G9: Shift II (7:00 - 15:00) | I9: Storage | J9: Shift III (15:00 - 23:00) | L9: Storage | M9: Shift I (23:00 - 7:00) | O9: Storage | P9: To Day | Q9: MTD | R9: D. Time
F10: MT/Day | G10: Product | H10: D.Time | I10: 122T... | J10: Product | K10: D.Time | L10: 122T... | M10: Product | N10: D.Time | O10: 122T... | R10: Hours
A11: 101 | C11: Feed Stream (C16-18 Raw Ester) | F11: 60 | G11: 18.6 | I11: T34 | J11: 20.2 | L11: T34 | M11: 22.5 | O11: T34 | P11: =G11+J11+M11 -> 61.3 | Q11: =P11+'08'!Q11 -> 357.3 | R11: =H11+K11+N11 -> 0
C12: Oleic Intermediate Stream | F12: 30 | G12: 11.5 | I12: T94/T95 | J12: 9.4 | L12: T94 | M12: 14 | O12: T94 | P12: =G12+J12+M12 -> 34.9 | Q12: =P12+'08'!Q12 -> 180.9 | R12: =H12+K12+N12 -> 0
C13: Heavy Phase Fraction | F13: 30 | G13: 7.9 | I13: T99 | J13: 12.7 | L13: T99 | M13: 8.3 | O13: T99 | P13: =G13+J13+M13 -> 28.9 | Q13: =P13+'08'!Q13 -> 140.9 | R13: =H13+K13+N13 -> 0
A14: 102 | C14: Feed Stream (Hydrogenated C16-18) | F14: 40 | P14: =G14+J14+M14 -> 0 | Q14: =P14+'08'!Q14 -> 158.894 | R14: =H14+K14+N14 -> 0
C15: Feed Stream (Hydrogenated Process Stock) | F15: 40 | P15: =G15+J15+M15 -> 0 | Q15: =P15+'08'!Q15 -> 0 | R15: =H15+K15+N15 -> 0
C16: Light Volatile Fraction | F16: =F14*(2/100) -> 0.8 | P16: =G16+J16+M16 -> 0 | Q16: =P16+'08'!Q16 -> 12.8787 | R16: =H16+K16+N16 -> 0
C17: Side Cut Fraction A | F17: =F14*12/100 -> 4.8 | P17: =G17+J17+M17 -> 0 | Q17: =P17+'08'!Q17 -> 0.227 | R17: =H17+K17+N17 -> 0
C18: Side Cut Fraction B | F18: - | P18: =G18+J18+M18 -> 0 | Q18: =P18+'08'!Q18 -> 102.732 | R18: =H18+K18+N18 -> 0
C19: Side Cut Fraction C | F19: - | P19: =G19+J19+M19 -> 0 | Q19: =P19+'08'!Q19 -> 34.469 | R19: =H19+K19+N19 -> 0
C20: Heavy Bottom Fraction | F20: - | P20: =G20+J20+M20 -> 0 | Q20: =P20+'08'!Q20 -> 0.806 | R20: =H20+K20+N20 -> 0
C21: Organic Residue Stream | F21: =F14*(0.5/100) -> 0.2 | P21: =G21+J21+M21 -> 0 | Q21: =P21+'08'!Q21 -> 7.8379 | R21: =H21+K21+N21 -> 0
A22: 102+ | C22: Feed Stream (C8-10 Process Input)) | F22: 24 | P22: =G22+J22+M22 -> 0 | Q22: =P22+'08'!Q22 -> 79.345 | R22: =H22+K22+N22 -> 0
C23: Hydrogenated Product Stream | F23: 24 | P23: =G23+J23+M23 -> 0 | Q23: =P23+'08'!Q23 -> 81.665 | R23: =H23+K23+N23 -> 0
A24: 103+ | C24: Light Hydrocarbon Fraction | F24: 24 | G24: 7.282 | I24: T114 | J24: 4.348 | L24: T114 | P24: =G24+J24+M24 -> 11.63 | Q24: =P24+'08'!Q24 -> 143.725 | R24: =H24+K24+N24 -> 0
C25: Light End (C6) | F25: - | G25: 0.2468 | I25: T117 | J25: 0.148 | L25: T117 | P25: =G25+J25+M25 -> 0.3948 | Q25: =P25+'08'!Q25 -> 4.3584 | R25: =H25+K25+N25 -> 0
C26: Distillation Side Cut A | F26: - | G26: 6.433 | I26: T117 | J26: 3.881 | L26: T117 | P26: =G26+J26+M26 -> 10.314 | Q26: =P26+'08'!Q26 -> 133.044 | R26: =H26+K26+N26 -> 0
C27: Distillation Side Cut B | F27: - | P27: =G27+J27+M27 -> 0 | Q27: =P27+'08'!Q27 -> 0 | R27: =H27+K27+N27 -> 0
C28: Heavy Residual Stream | F28: - | G28: 0.528 | I28: T107 | J28: 0.3597 | L28: T107 | P28: =G28+J28+M28 -> 0.8877 | Q28: =P28+'08'!Q28 -> 7.2943 | R28: =H28+K28+N28 -> 0
A29: 104 | C29: Feed Primary Stream (C8-10) | M29: 12.221 | O29: T120 | P29: =G29+J29+M29 -> 12.221 | Q29: =P29+'08'!Q29 -> 86.616 | R29: =H29+K29+N29 -> 0
C30: Feed Secondary Stream (Oleic Intermediate) | P30: =G30+J30+M30 -> 0 | Q30: =P30+'08'!Q30 -> 0 | R30: =H30+K30+N30 -> 0
C31: Feed Stream Auxiliary (Glycerol Phase) | M31: 2.465 | O31: T124 | P31: =G31+J31+M31 -> 2.465 | Q31: =P31+'08'!Q31 -> 17.265 | R31: =H31+K31+N31 -> 0
C32: Product Stream A (Medium Chain Ester) | G32: 3.517 | I32: T127 | J32: 9.471 | L32: T127 | P32: =G32+J32+M32 -> 12.988 | Q32: =P32+'08'!Q32 -> 87.362 | R32: =H32+K32+N32 -> 0
C33: Product Stream B (Distilled Chemical Output) | P33: =G33+J33+M33 -> 0 | Q33: =P33+'08'!Q33 -> 0 | R33: =H33+K33+N33 -> 0

Sheet 10
A5: Operation Month | D5: ='01'!D5 -> February | E5: ='01'!E5 -> 2026
A6: Operation Date | D6: ='09'!D6+1 -> 46063
A8: I. Production
A9: Sect. | C9: Description | F9: Capacity | G9: Shift II (7:00 - 15:00) | I9: Storage | J9: Shift III (15:00 - 23:00) | L9: Storage | M9: Shift I (23:00 - 7:00) | O9: Storage | P9: To Day | Q9: MTD | R9: D. Time
F10: MT/Day | G10: Product | H10: D.Time | I10: 122T... | J10: Product | K10: D.Time | L10: 122T... | M10: Product | N10: D.Time | O10: 122T... | R10: Hours
A11: 101 | C11: Feed Stream (C16-18 Raw Ester) | F11: 60 | G11: 19.2 | I11: T34 | J11: 20.1 | L11: T34 | M11: 22.9 | O11: T34 | P11: =G11+J11+M11 -> 62.2 | Q11: =P11+'09'!Q11 -> 419.5 | R11: =H11+K11+N11 -> 0
C12: Oleic Intermediate Stream | F12: 30 | G12: 10.2 | I12: T94 | J12: 9.9 | L12: T94 | M12: 14.1 | O12: T94 | P12: =G12+J12+M12 -> 34.2 | Q12: =P12+'09'!Q12 -> 215.1 | R12: =H12+K12+N12 -> 0
C13: Heavy Phase Fraction | F13: 30 | G13: 5.8 | I13: T99 | J13: 11.6 | L13: T99 | M13: 8.7 | O13: T99 | P13: =G13+J13+M13 -> 26.1 | Q13: =P13+'09'!Q13 -> 167 | R13: =H13+K13+N13 -> 0
A14: 102 | C14: Feed Stream (Hydrogenated C16-18) | F14: 40 | P14: =G14+J14+M14 -> 0 | Q14: =P14+'09'!Q14 -> 158.894 | R14: =H14+K14+N14 -> 0
C15: Feed Stream (Hydrogenated Process Stock) | F15: 40 | P15: =G15+J15+M15 -> 0 | Q15: =P15+'09'!Q15 -> 0 | R15: =H15+K15+N15 -> 0
C16: Light Volatile Fraction | F16: =F14*(2/100) -> 0.8 | P16: =G16+J16+M16 -> 0 | Q16: =P16+'09'!Q16 -> 12.8787 | R16: =H16+K16+N16 -> 0
C17: Side Cut Fraction A | F17: =F14*12/100 -> 4.8 | P17: =G17+J17+M17 -> 0 | Q17: =P17+'09'!Q17 -> 0.227 | R17: =H17+K17+N17 -> 0
C18: Side Cut Fraction B | F18: - | P18: =G18+J18+M18 -> 0 | Q18: =P18+'09'!Q18 -> 102.732 | R18: =H18+K18+N18 -> 0
C19: Side Cut Fraction C | F19: - | P19: =G19+J19+M19 -> 0 | Q19: =P19+'09'!Q19 -> 34.469 | R19: =H19+K19+N19 -> 0
C20: Heavy Bottom Fraction | F20: - | P20: =G20+J20+M20 -> 0 | Q20: =P20+'09'!Q20 -> 0.806 | R20: =H20+K20+N20 -> 0
C21: Organic Residue Stream | F21: =F14*(0.5/100) -> 0.2 | P21: =G21+J21+M21 -> 0 | Q21: =P21+'09'!Q21 -> 7.8379 | R21: =H21+K21+N21 -> 0
A22: 102+ | C22: Feed Stream (C8-10 Process Input)) | F22: 24 | P22: =G22+J22+M22 -> 0 | Q22: =P22+'09'!Q22 -> 79.345 | R22: =H22+K22+N22 -> 0
C23: Hydrogenated Product Stream | F23: 24 | P23: =G23+J23+M23 -> 0 | Q23: =P23+'09'!Q23 -> 81.665 | R23: =H23+K23+N23 -> 0
A24: 103+ | C24: Light Hydrocarbon Fraction | F24: 24 | P24: =G24+J24+M24 -> 0 | Q24: =P24+'09'!Q24 -> 143.725 | R24: =H24+K24+N24 -> 0
C25: Light End (C6) | F25: - | P25: =G25+J25+M25 -> 0 | Q25: =P25+'09'!Q25 -> 4.3584 | R25: =H25+K25+N25 -> 0
C26: Distillation Side Cut A | F26: - | P26: =G26+J26+M26 -> 0 | Q26: =P26+'09'!Q26 -> 133.044 | R26: =H26+K26+N26 -> 0
C27: Distillation Side Cut B | F27: - | P27: =G27+J27+M27 -> 0 | Q27: =P27+'09'!Q27 -> 0 | R27: =H27+K27+N27 -> 0
C28: Heavy Residual Stream | F28: - | P28: =G28+J28+M28 -> 0 | Q28: =P28+'09'!Q28 -> 7.2943 | R28: =H28+K28+N28 -> 0
A29: 104 | C29: Feed Primary Stream (C8-10) | P29: =G29+J29+M29 -> 0 | Q29: =P29+'09'!Q29 -> 86.616 | R29: =H29+K29+N29 -> 0
C30: Feed Secondary Stream (Oleic Intermediate) | P30: =G30+J30+M30 -> 0 | Q30: =P30+'09'!Q30 -> 0 | R30: =H30+K30+N30 -> 0
C31: Feed Stream Auxiliary (Glycerol Phase) | P31: =G31+J31+M31 -> 0 | Q31: =P31+'09'!Q31 -> 17.265 | R31: =H31+K31+N31 -> 0
C32: Product Stream A (Medium Chain Ester) | J32: 1.984 | L32: T127 | M32: 10.973 | O32: T127 | P32: =G32+J32+M32 -> 12.957 | Q32: =P32+'09'!Q32 -> 100.319 | R32: =H32+K32+N32 -> 0
C33: Product Stream B (Distilled Chemical Output) | P33: =G33+J33+M33 -> 0 | Q33: =P33+'09'!Q33 -> 0 | R33: =H33+K33+N33 -> 0

Sheet 11
A5: Operation Month | D5: ='01'!D5 -> February | E5: ='01'!E5 -> 2026
A6: Operation Date | D6: ='10'!D6+1 -> 46064
A8: I. Production
A9: Sect. | C9: Description | F9: Capacity | G9: Shift II (7:00 - 15:00) | I9: Storage | J9: Shift III (15:00 - 23:00) | L9: Storage | M9: Shift I (23:00 - 7:00) | O9: Storage | P9: To Day | Q9: MTD | R9: D. Time
F10: MT/Day | G10: Product | H10: D.Time | I10: 122T... | J10: Product | K10: D.Time | L10: 122T... | M10: Product | N10: D.Time | O10: 122T... | R10: Hours
A11: 101 | C11: Feed Stream (C16-18 Raw Ester) | F11: 60 | G11: 18.5 | I11: T34 | J11: 20.2 | L11: T34 | M11: 22.6 | O11: T34 | P11: =G11+J11+M11 -> 61.3 | Q11: =P11+'10'!Q11 -> 480.8 | R11: =H11+K11+N11 -> 0
C12: Oleic Intermediate Stream | F12: 30 | G12: 9.9 | I12: T94 | J12: 10.1 | L12: T94 | M12: 14.1 | O12: T94 | P12: =G12+J12+M12 -> 34.1 | Q12: =P12+'10'!Q12 -> 249.2 | R12: =H12+K12+N12 -> 0
C13: Heavy Phase Fraction | F13: 30 | G13: 8.7 | I13: T99 | J13: 8.8 | L13: T99 | M13: 8.8 | O13: T99 | P13: =G13+J13+M13 -> 26.3 | Q13: =P13+'10'!Q13 -> 193.3 | R13: =H13+K13+N13 -> 0
A14: 102 | C14: Feed Stream (Hydrogenated C16-18) | F14: 40 | P14: =G14+J14+M14 -> 0 | Q14: =P14+'10'!Q14 -> 158.894 | R14: =H14+K14+N14 -> 0
C15: Feed Stream (Hydrogenated Process Stock) | F15: 40 | P15: =G15+J15+M15 -> 0 | Q15: =P15+'10'!Q15 -> 0 | R15: =H15+K15+N15 -> 0
C16: Light Volatile Fraction | F16: =F14*(2/100) -> 0.8 | P16: =G16+J16+M16 -> 0 | Q16: =P16+'10'!Q16 -> 12.8787 | R16: =H16+K16+N16 -> 0
C17: Side Cut Fraction A | F17: =F14*12/100 -> 4.8 | P17: =G17+J17+M17 -> 0 | Q17: =P17+'10'!Q17 -> 0.227 | R17: =H17+K17+N17 -> 0
C18: Side Cut Fraction B | F18: - | P18: =G18+J18+M18 -> 0 | Q18: =P18+'10'!Q18 -> 102.732 | R18: =H18+K18+N18 -> 0
C19: Side Cut Fraction C | F19: - | P19: =G19+J19+M19 -> 0 | Q19: =P19+'10'!Q19 -> 34.469 | R19: =H19+K19+N19 -> 0
C20: Heavy Bottom Fraction | F20: - | P20: =G20+J20+M20 -> 0 | Q20: =P20+'10'!Q20 -> 0.806 | R20: =H20+K20+N20 -> 0
C21: Organic Residue Stream | F21: =F14*(0.5/100) -> 0.2 | P21: =G21+J21+M21 -> 0 | Q21: =P21+'10'!Q21 -> 7.8379 | R21: =H21+K21+N21 -> 0
A22: 102+ | C22: Feed Stream (C8-10 Process Input)) | F22: 24 | P22: =G22+J22+M22 -> 0 | Q22: =P22+'10'!Q22 -> 79.345 | R22: =H22+K22+N22 -> 0
C23: Hydrogenated Product Stream | F23: 24 | P23: =G23+J23+M23 -> 0 | Q23: =P23+'10'!Q23 -> 81.665 | R23: =H23+K23+N23 -> 0
A24: 103+ | C24: Light Hydrocarbon Fraction | F24: 24 | P24: =G24+J24+M24 -> 0 | Q24: =P24+'10'!Q24 -> 143.725 | R24: =H24+K24+N24 -> 0
C25: Light End (C6) | F25: - | P25: =G25+J25+M25 -> 0 | Q25: =P25+'10'!Q25 -> 4.3584 | R25: =H25+K25+N25 -> 0
C26: Distillation Side Cut A | F26: - | P26: =G26+J26+M26 -> 0 | Q26: =P26+'10'!Q26 -> 133.044 | R26: =H26+K26+N26 -> 0
C27: Distillation Side Cut B | F27: - | P27: =G27+J27+M27 -> 0 | Q27: =P27+'10'!Q27 -> 0 | R27: =H27+K27+N27 -> 0
C28: Heavy Residual Stream | F28: - | P28: =G28+J28+M28 -> 0 | Q28: =P28+'10'!Q28 -> 7.2943 | R28: =H28+K28+N28 -> 0
A29: 104 | C29: Feed Primary Stream (C8-10) | G29: 12.323 | I29: T120 | J29: 0 | L29: T120 | M29: 0 | O29: T120 | P29: =G29+J29+M29 -> 12.323 | Q29: =P29+'10'!Q29 -> 98.939 | R29: =H29+K29+N29 -> 0
C30: Feed Secondary Stream (Oleic Intermediate) | P30: =G30+J30+M30 -> 0 | Q30: =P30+'10'!Q30 -> 0 | R30: =H30+K30+N30 -> 0
C31: Feed Stream Auxiliary (Glycerol Phase) | G31: 2.467 | I31: T124 | J31: 0 | L31: T124 | M31: 0 | O31: T124 | P31: =G31+J31+M31 -> 2.467 | Q31: =P31+'10'!Q31 -> 19.732 | R31: =H31+K31+N31 -> 0
C32: Product Stream A (Medium Chain Ester) | M32: 1.792 | O32: T127 | P32: =G32+J32+M32 -> 1.792 | Q32: =P32+'10'!Q32 -> 102.111 | R32: =H32+K32+N32 -> 0
C33: Product Stream B (Distilled Chemical Output) | P33: =G33+J33+M33 -> 0 | Q33: =P33+'10'!Q33 -> 0 | R33: =H33+K33+N33 -> 0

Sheet 12
A5: Operation Month | D5: ='01'!D5 -> February | E5: ='01'!E5 -> 2026
A6: Operation Date | D6: ='11'!D6+1 -> 46065
A8: I. Production
A9: Sect. | C9: Description | F9: Capacity | G9: Shift II (7:00 - 15:00) | I9: Storage | J9: Shift III (15:00 - 23:00) | L9: Storage | M9: Shift I (23:00 - 7:00) | O9: Storage | P9: To Day | Q9: MTD | R9: D. Time
F10: MT/Day | G10: Product | H10: D.Time | I10: 122T... | J10: Product | K10: D.Time | L10: 122T... | M10: Product | N10: D.Time | O10: 122T... | R10: Hours
A11: 101 | C11: Feed Stream (C16-18 Raw Ester) | F11: 60 | G11: 17.6 | I11: T34 | J11: 19.7 | L11: T34 | M11: 23.2 | O11: T34 | P11: =G11+J11+M11 -> 60.5 | Q11: =P11+'11'!Q11 -> 541.3 | R11: =H11+K11+N11 -> 0
C12: Oleic Intermediate Stream | F12: 30 | G12: 10.2 | I12: T94 | J12: 10 | L12: T94 | M12: 13.8 | O12: T94 | P12: =G12+J12+M12 -> 34 | Q12: =P12+'11'!Q12 -> 283.2 | R12: =H12+K12+N12 -> 0
C13: Heavy Phase Fraction | F13: 30 | G13: 7.4 | I13: T99 | J13: 9.3 | L13: T99 | M13: 9.3 | O13: T99 | P13: =G13+J13+M13 -> 26 | Q13: =P13+'11'!Q13 -> 219.3 | R13: =H13+K13+N13 -> 0
A14: 102 | C14: Feed Stream (Hydrogenated C16-18) | F14: 40 | P14: =G14+J14+M14 -> 0 | Q14: =P14+'11'!Q14 -> 158.894 | R14: =H14+K14+N14 -> 0
C15: Feed Stream (Hydrogenated Process Stock) | F15: 40 | P15: =G15+J15+M15 -> 0 | Q15: =P15+'11'!Q15 -> 0 | R15: =H15+K15+N15 -> 0
C16: Light Volatile Fraction | F16: =F14*(2/100) -> 0.8 | P16: =G16+J16+M16 -> 0 | Q16: =P16+'11'!Q16 -> 12.8787 | R16: =H16+K16+N16 -> 0
C17: Side Cut Fraction A | F17: =F14*12/100 -> 4.8 | P17: =G17+J17+M17 -> 0 | Q17: =P17+'11'!Q17 -> 0.227 | R17: =H17+K17+N17 -> 0
C18: Side Cut Fraction B | F18: - | P18: =G18+J18+M18 -> 0 | Q18: =P18+'11'!Q18 -> 102.732 | R18: =H18+K18+N18 -> 0
C19: Side Cut Fraction C | F19: - | P19: =G19+J19+M19 -> 0 | Q19: =P19+'11'!Q19 -> 34.469 | R19: =H19+K19+N19 -> 0
C20: Heavy Bottom Fraction | F20: - | P20: =G20+J20+M20 -> 0 | Q20: =P20+'11'!Q20 -> 0.806 | R20: =H20+K20+N20 -> 0
C21: Organic Residue Stream | F21: =F14*(0.5/100) -> 0.2 | P21: =G21+J21+M21 -> 0 | Q21: =P21+'11'!Q21 -> 7.8379 | R21: =H21+K21+N21 -> 0
A22: 102+ | C22: Feed Stream (C8-10 Process Input)) | F22: 24 | P22: =G22+J22+M22 -> 0 | Q22: =P22+'11'!Q22 -> 79.345 | R22: =H22+K22+N22 -> 0
C23: Hydrogenated Product Stream | F23: 24 | P23: =G23+J23+M23 -> 0 | Q23: =P23+'11'!Q23 -> 81.665 | R23: =H23+K23+N23 -> 0
A24: 103+ | C24: Light Hydrocarbon Fraction | F24: 24 | P24: =G24+J24+M24 -> 0 | Q24: =P24+'11'!Q24 -> 143.725 | R24: =H24+K24+N24 -> 0
C25: Light End (C6) | F25: - | P25: =G25+J25+M25 -> 0 | Q25: =P25+'11'!Q25 -> 4.3584 | R25: =H25+K25+N25 -> 0
C26: Distillation Side Cut A | F26: - | P26: =G26+J26+M26 -> 0 | Q26: =P26+'11'!Q26 -> 133.044 | R26: =H26+K26+N26 -> 0
C27: Distillation Side Cut B | F27: - | P27: =G27+J27+M27 -> 0 | Q27: =P27+'11'!Q27 -> 0 | R27: =H27+K27+N27 -> 0
C28: Heavy Residual Stream | F28: - | P28: =G28+J28+M28 -> 0 | Q28: =P28+'11'!Q28 -> 7.2943 | R28: =H28+K28+N28 -> 0
A29: 104 | C29: Feed Primary Stream (C8-10) | J29: 12.666 | L29: T120 | M29: 0 | O29: T120 | P29: =G29+J29+M29 -> 12.666 | Q29: =P29+'11'!Q29 -> 111.605 | R29: =H29+K29+N29 -> 0
C30: Feed Secondary Stream (Oleic Intermediate) | P30: =G30+J30+M30 -> 0 | Q30: =P30+'11'!Q30 -> 0 | R30: =H30+K30+N30 -> 0
C31: Feed Stream Auxiliary (Glycerol Phase) | J31: 2.469 | L31: T124 | M31: 0 | O31: T124 | P31: =G31+J31+M31 -> 2.469 | Q31: =P31+'11'!Q31 -> 22.201 | R31: =H31+K31+N31 -> 0
C32: Product Stream A (Medium Chain Ester) | G32: 5.75 | I32: T129 | J32: 4.915 | L32: T129 | M32: 0 | O32: T129 | P32: =G32+J32+M32 -> 10.665 | Q32: =P32+'11'!Q32 -> 112.776 | R32: =H32+K32+N32 -> 0
C33: Product Stream B (Distilled Chemical Output) | P33: =G33+J33+M33 -> 0 | Q33: =P33+'11'!Q33 -> 0 | R33: =H33+K33+N33 -> 0

Sheet 13
A5: Operation Month | D5: ='01'!D5 -> February | E5: ='01'!E5 -> 2026
A6: Operation Date | D6: ='12'!D6+1 -> 46066
A8: I. Production
A9: Sect. | C9: Description | F9: Capacity | G9: Shift II (7:00 - 15:00) | I9: Storage | J9: Shift III (15:00 - 23:00) | L9: Storage | M9: Shift I (23:00 - 7:00) | O9: Storage | P9: To Day | Q9: MTD | R9: D. Time
F10: MT/Day | G10: Product | H10: D.Time | I10: 122T... | J10: Product | K10: D.Time | L10: 122T... | M10: Product | N10: D.Time | O10: 122T... | R10: Hours
A11: 101 | C11: Feed Stream (C16-18 Raw Ester) | F11: 60 | G11: 18.6 | I11: T34 | J11: 22.6 | L11: T34 | M11: 20 | O11: T34 | P11: =G11+J11+M11 -> 61.2 | Q11: =P11+'12'!Q11 -> 602.5 | R11: =H11+K11+N11 -> 0
C12: Oleic Intermediate Stream | F12: 30 | G12: 9.7 | I12: T94 | J12: 9.9 | L12: T94 | M12: 14.1 | O12: T94 | P12: =G12+J12+M12 -> 33.7 | Q12: =P12+'12'!Q12 -> 316.9 | R12: =H12+K12+N12 -> 0
C13: Heavy Phase Fraction | F13: 30 | G13: 7.2 | I13: T99 | J13: 13.7 | L13: T99 | M13: 9.3 | O13: T99 | P13: =G13+J13+M13 -> 30.2 | Q13: =P13+'12'!Q13 -> 249.5 | R13: =H13+K13+N13 -> 0
A14: 102 | C14: Feed Stream (Hydrogenated C16-18) | F14: 40 | P14: =G14+J14+M14 -> 0 | Q14: =P14+'12'!Q14 -> 158.894 | R14: =H14+K14+N14 -> 0
C15: Feed Stream (Hydrogenated Process Stock) | F15: 40 | P15: =G15+J15+M15 -> 0 | Q15: =P15+'12'!Q15 -> 0 | R15: =H15+K15+N15 -> 0
C16: Light Volatile Fraction | F16: =F14*(2/100) -> 0.8 | P16: =G16+J16+M16 -> 0 | Q16: =P16+'12'!Q16 -> 12.8787 | R16: =H16+K16+N16 -> 0
C17: Side Cut Fraction A | F17: =F14*12/100 -> 4.8 | P17: =G17+J17+M17 -> 0 | Q17: =P17+'12'!Q17 -> 0.227 | R17: =H17+K17+N17 -> 0
C18: Side Cut Fraction B | F18: - | P18: =G18+J18+M18 -> 0 | Q18: =P18+'12'!Q18 -> 102.732 | R18: =H18+K18+N18 -> 0
C19: Side Cut Fraction C | F19: - | P19: =G19+J19+M19 -> 0 | Q19: =P19+'12'!Q19 -> 34.469 | R19: =H19+K19+N19 -> 0
C20: Heavy Bottom Fraction | F20: - | P20: =G20+J20+M20 -> 0 | Q20: =P20+'12'!Q20 -> 0.806 | R20: =H20+K20+N20 -> 0
C21: Organic Residue Stream | F21: =F14*(0.5/100) -> 0.2 | P21: =G21+J21+M21 -> 0 | Q21: =P21+'12'!Q21 -> 7.8379 | R21: =H21+K21+N21 -> 0
A22: 102+ | C22: Feed Stream (C8-10 Process Input)) | F22: 24 | P22: =G22+J22+M22 -> 0 | Q22: =P22+'12'!Q22 -> 79.345 | R22: =H22+K22+N22 -> 0
C23: Hydrogenated Product Stream | F23: 24 | P23: =G23+J23+M23 -> 0 | Q23: =P23+'12'!Q23 -> 81.665 | R23: =H23+K23+N23 -> 0
A24: 103+ | C24: Light Hydrocarbon Fraction | F24: 24 | P24: =G24+J24+M24 -> 0 | Q24: =P24+'12'!Q24 -> 143.725 | R24: =H24+K24+N24 -> 0
C25: Light End (C6) | F25: - | P25: =G25+J25+M25 -> 0 | Q25: =P25+'12'!Q25 -> 4.3584 | R25: =H25+K25+N25 -> 0
C26: Distillation Side Cut A | F26: - | P26: =G26+J26+M26 -> 0 | Q26: =P26+'12'!Q26 -> 133.044 | R26: =H26+K26+N26 -> 0
C27: Distillation Side Cut B | F27: - | P27: =G27+J27+M27 -> 0 | Q27: =P27+'12'!Q27 -> 0 | R27: =H27+K27+N27 -> 0
C28: Heavy Residual Stream | F28: - | P28: =G28+J28+M28 -> 0 | Q28: =P28+'12'!Q28 -> 7.2943 | R28: =H28+K28+N28 -> 0
A29: 104 | C29: Feed Primary Stream (C8-10) | P29: =G29+J29+M29 -> 0 | Q29: =P29+'12'!Q29 -> 111.605 | R29: =H29+K29+N29 -> 0
C30: Feed Secondary Stream (Oleic Intermediate) | P30: =G30+J30+M30 -> 0 | Q30: =P30+'12'!Q30 -> 0 | R30: =H30+K30+N30 -> 0
C31: Feed Stream Auxiliary (Glycerol Phase) | P31: =G31+J31+M31 -> 0 | Q31: =P31+'12'!Q31 -> 22.201 | R31: =H31+K31+N31 -> 0
C32: Product Stream A (Medium Chain Ester) | G32: 0 | I32: T129 | J32: 8.8 | L32: T129 | M32: 4.164 | O32: T129 | P32: =G32+J32+M32 -> 12.964 | Q32: =P32+'12'!Q32 -> 125.74 | R32: =H32+K32+N32 -> 0
C33: Product Stream B (Distilled Chemical Output) | P33: =G33+J33+M33 -> 0 | Q33: =P33+'12'!Q33 -> 0 | R33: =H33+K33+N33 -> 0

Sheet 14
A5: Operation Month | D5: ='01'!D5 -> February | E5: ='01'!E5 -> 2026
A6: Operation Date | D6: ='13'!D6+1 -> 46067
A8: I. Production
A9: Sect. | C9: Description | F9: Capacity | G9: Shift II (7:00 - 15:00) | I9: Storage | J9: Shift III (15:00 - 23:00) | L9: Storage | M9: Shift I (23:00 - 7:00) | O9: Storage | P9: To Day | Q9: MTD | R9: D. Time
F10: MT/Day | G10: Product | H10: D.Time | I10: 122T... | J10: Product | K10: D.Time | L10: 122T... | M10: Product | N10: D.Time | O10: 122T... | R10: Hours
A11: 101 | C11: Feed Stream (C16-18 Raw Ester) | F11: 60 | G11: 18.8 | I11: T34 | J11: 23.6 | L11: T34 | M11: 19.4 | O11: T34 | P11: =G11+J11+M11 -> 61.8 | Q11: =P11+'13'!Q11 -> 664.3 | R11: =H11+K11+N11 -> 0
C12: Oleic Intermediate Stream | F12: 30 | G12: 9.8 | I12: T94 | J12: 9.3 | L12: T94 | M12: 13.1 | O12: T94 | P12: =G12+J12+M12 -> 32.2 | Q12: =P12+'13'!Q12 -> 349.1 | R12: =H12+K12+N12 -> 0
C13: Heavy Phase Fraction | F13: 30 | G13: 7.8 | I13: T99 | J13: 11.9 | L13: T99 | M13: 9.3 | O13: T99 | P13: =G13+J13+M13 -> 29 | Q13: =P13+'13'!Q13 -> 278.5 | R13: =H13+K13+N13 -> 0
A14: 102 | C14: Feed Stream (Hydrogenated C16-18) | F14: 40 | P14: =G14+J14+M14 -> 0 | Q14: =P14+'13'!Q14 -> 158.894 | R14: =H14+K14+N14 -> 0
C15: Feed Stream (Hydrogenated Process Stock) | F15: 40 | P15: =G15+J15+M15 -> 0 | Q15: =P15+'13'!Q15 -> 0 | R15: =H15+K15+N15 -> 0
C16: Light Volatile Fraction | F16: =F14*(2/100) -> 0.8 | P16: =G16+J16+M16 -> 0 | Q16: =P16+'13'!Q16 -> 12.8787 | R16: =H16+K16+N16 -> 0
C17: Side Cut Fraction A | F17: =F14*12/100 -> 4.8 | P17: =G17+J17+M17 -> 0 | Q17: =P17+'13'!Q17 -> 0.227 | R17: =H17+K17+N17 -> 0
C18: Side Cut Fraction B | F18: - | P18: =G18+J18+M18 -> 0 | Q18: =P18+'13'!Q18 -> 102.732 | R18: =H18+K18+N18 -> 0
C19: Side Cut Fraction C | F19: - | P19: =G19+J19+M19 -> 0 | Q19: =P19+'13'!Q19 -> 34.469 | R19: =H19+K19+N19 -> 0
C20: Heavy Bottom Fraction | F20: - | P20: =G20+J20+M20 -> 0 | Q20: =P20+'13'!Q20 -> 0.806 | R20: =H20+K20+N20 -> 0
C21: Organic Residue Stream | F21: =F14*(0.5/100) -> 0.2 | P21: =G21+J21+M21 -> 0 | Q21: =P21+'13'!Q21 -> 7.8379 | R21: =H21+K21+N21 -> 0
A22: 102+ | C22: Feed Stream (C8-10 Process Input)) | F22: 24 | G22: 8.811 | I22: T24 | J22: 8.812 | L22: T24 | M22: 7.652 | O22: T24 | P22: =G22+J22+M22 -> 25.275 | Q22: =P22+'13'!Q22 -> 104.62 | R22: =H22+K22+N22 -> 0
C23: Hydrogenated Product Stream | F23: 24 | J23: 6.292 | L23: T112 | M23: 8.004 | O23: T112 | P23: =G23+J23+M23 -> 14.296 | Q23: =P23+'13'!Q23 -> 95.961 | R23: =H23+K23+N23 -> 0
A24: 103+ | C24: Light Hydrocarbon Fraction | F24: 24 | P24: =G24+J24+M24 -> 0 | Q24: =P24+'13'!Q24 -> 143.725 | R24: =H24+K24+N24 -> 0
C25: Light End (C6) | F25: - | P25: =G25+J25+M25 -> 0 | Q25: =P25+'13'!Q25 -> 4.3584 | R25: =H25+K25+N25 -> 0
C26: Distillation Side Cut A | F26: - | P26: =G26+J26+M26 -> 0 | Q26: =P26+'13'!Q26 -> 133.044 | R26: =H26+K26+N26 -> 0
C27: Distillation Side Cut B | F27: - | P27: =G27+J27+M27 -> 0 | Q27: =P27+'13'!Q27 -> 0 | R27: =H27+K27+N27 -> 0
C28: Heavy Residual Stream | F28: - | P28: =G28+J28+M28 -> 0 | Q28: =P28+'13'!Q28 -> 7.2943 | R28: =H28+K28+N28 -> 0
A29: 104 | C29: Feed Primary Stream (C8-10) | P29: =G29+J29+M29 -> 0 | Q29: =P29+'13'!Q29 -> 111.605 | R29: =H29+K29+N29 -> 0
C30: Feed Secondary Stream (Oleic Intermediate) | P30: =G30+J30+M30 -> 0 | Q30: =P30+'13'!Q30 -> 0 | R30: =H30+K30+N30 -> 0
C31: Feed Stream Auxiliary (Glycerol Phase) | P31: =G31+J31+M31 -> 0 | Q31: =P31+'13'!Q31 -> 22.201 | R31: =H31+K31+N31 -> 0
C32: Product Stream A (Medium Chain Ester) | L32: T129 | M32: 9.111 | O32: T129 | P32: =G32+J32+M32 -> 9.111 | Q32: =P32+'13'!Q32 -> 134.851 | R32: =H32+K32+N32 -> 0
C33: Product Stream B (Distilled Chemical Output) | P33: =G33+J33+M33 -> 0 | Q33: =P33+'13'!Q33 -> 0 | R33: =H33+K33+N33 -> 0

Sheet 15
A5: Operation Month | D5: ='01'!D5 -> February | E5: ='01'!E5 -> 2026
A6: Operation Date | D6: ='14'!D6+1 -> 46068
A8: I. Production
A9: Sect. | C9: Description | F9: Capacity | G9: Shift II (7:00 - 15:00) | I9: Storage | J9: Shift III (15:00 - 23:00) | L9: Storage | M9: Shift I (23:00 - 7:00) | O9: Storage | P9: To Day | Q9: MTD | R9: D. Time
F10: MT/Day | G10: Product | H10: D.Time | I10: 122T... | J10: Product | K10: D.Time | L10: 122T... | M10: Product | N10: D.Time | O10: 122T... | R10: Hours
A11: 101 | C11: Feed Stream (C16-18 Raw Ester) | F11: 60 | G11: 19.2 | I11: T34 | J11: 21 | L11: T34 | M11: 21 | O11: T34 | P11: =G11+J11+M11 -> 61.2 | Q11: =P11+'14'!Q11 -> 725.5 | R11: =H11+K11+N11 -> 0
C12: Oleic Intermediate Stream | F12: 30 | G12: 9.9 | I12: T94 | J12: 9.4 | L12: T94 | M12: 13.4 | O12: T94 | P12: =G12+J12+M12 -> 32.7 | Q12: =P12+'14'!Q12 -> 381.8 | R12: =H12+K12+N12 -> 0
C13: Heavy Phase Fraction | F13: 30 | G13: 7 | I13: T99 | J13: 11.5 | L13: T99 | M13: 7 | O13: T99 | P13: =G13+J13+M13 -> 25.5 | Q13: =P13+'14'!Q13 -> 304 | R13: =H13+K13+N13 -> 0
A14: 102 | C14: Feed Stream (Hydrogenated C16-18) | F14: 40 | P14: =G14+J14+M14 -> 0 | Q14: =P14+'14'!Q14 -> 158.894 | R14: =H14+K14+N14 -> 0
C15: Feed Stream (Hydrogenated Process Stock) | F15: 40 | P15: =G15+J15+M15 -> 0 | Q15: =P15+'14'!Q15 -> 0 | R15: =H15+K15+N15 -> 0
C16: Light Volatile Fraction | F16: =F14*(2/100) -> 0.8 | P16: =G16+J16+M16 -> 0 | Q16: =P16+'14'!Q16 -> 12.8787 | R16: =H16+K16+N16 -> 0
C17: Side Cut Fraction A | F17: =F14*12/100 -> 4.8 | P17: =G17+J17+M17 -> 0 | Q17: =P17+'14'!Q17 -> 0.227 | R17: =H17+K17+N17 -> 0
C18: Side Cut Fraction B | F18: - | P18: =G18+J18+M18 -> 0 | Q18: =P18+'14'!Q18 -> 102.732 | R18: =H18+K18+N18 -> 0
C19: Side Cut Fraction C | F19: - | P19: =G19+J19+M19 -> 0 | Q19: =P19+'14'!Q19 -> 34.469 | R19: =H19+K19+N19 -> 0
C20: Heavy Bottom Fraction | F20: - | P20: =G20+J20+M20 -> 0 | Q20: =P20+'14'!Q20 -> 0.806 | R20: =H20+K20+N20 -> 0
C21: Organic Residue Stream | F21: =F14*(0.5/100) -> 0.2 | P21: =G21+J21+M21 -> 0 | Q21: =P21+'14'!Q21 -> 7.8379 | R21: =H21+K21+N21 -> 0
A22: 102+ | C22: Feed Stream (C8-10 Process Input)) | F22: 24 | G22: 9.036 | I22: T24 | J22: 9.54 | L22: T24 | M22: 7.329 | O22: T24 | P22: =G22+J22+M22 -> 25.905 | Q22: =P22+'14'!Q22 -> 130.525 | R22: =H22+K22+N22 -> 0
C23: Hydrogenated Product Stream | F23: 24 | G23: 7.845 | I23: T112 | J23: 8.326 | L23: T112 | M23: 8.278 | O23: T112 | P23: =G23+J23+M23 -> 24.449 | Q23: =P23+'14'!Q23 -> 120.41 | R23: =H23+K23+N23 -> 0
A24: 103+ | C24: Light Hydrocarbon Fraction | F24: 24 | I24: T112 | J24: 8.521 | L24: T112 | M24: 8.712 | O24: T112 | P24: =G24+J24+M24 -> 17.233 | Q24: =P24+'14'!Q24 -> 160.958 | R24: =H24+K24+N24 -> 0
C25: Light End (C6) | F25: - | I25: T114 | J25: 0.1666 | L25: T114 | M25: 0.152 | O25: T114 | P25: =G25+J25+M25 -> 0.3186 | Q25: =P25+'14'!Q25 -> 4.677 | R25: =H25+K25+N25 -> 0
C26: Distillation Side Cut A | F26: - | I26: T115 | J26: 8.025 | L26: T115 | M26: 8.219 | O26: T115 | P26: =G26+J26+M26 -> 16.244 | Q26: =P26+'14'!Q26 -> 149.288 | R26: =H26+K26+N26 -> 0
C27: Distillation Side Cut B | F27: - | I27: Coloum | J27: 0 | L27: Coloum | M27: 0 | O27: coloum | P27: =G27+J27+M27 -> 0 | Q27: =P27+'14'!Q27 -> 0 | R27: =H27+K27+N27 -> 0
C28: Heavy Residual Stream | F28: - | I28: T119 | J28: 0.3299 | L28: T119 | M28: 0.367 | O28: T119 | P28: =G28+J28+M28 -> 0.6969 | Q28: =P28+'14'!Q28 -> 7.9912 | R28: =H28+K28+N28 -> 0
A29: 104 | C29: Feed Primary Stream (C8-10) | P29: =G29+J29+M29 -> 0 | Q29: =P29+'14'!Q29 -> 111.605 | R29: =H29+K29+N29 -> 0
C30: Feed Secondary Stream (Oleic Intermediate) | P30: =G30+J30+M30 -> 0 | Q30: =P30+'14'!Q30 -> 0 | R30: =H30+K30+N30 -> 0
